<?xml version="1.0"?>
<robot xmlns:xacro="http://www.ros.org/wiki/xacro">

	<xacro:macro name="six_dof" params="parent prefix *origin">
		<joint name="${prefix}base_joint" type="fixed">
			<parent link="${parent}" />
			<child link="${prefix}motor_link1" />
			<origin xyz="0 -3.3 0" rpy="0 0 0" />
		</joint>

		<!-- Link 1 -->
		<link name="${prefix}motor_link1">
			<visual>
				<origin xyz="0 0 0" rpy="0 0 0" />
				<geometry>
					<mesh filename="package://synapticon_ros2_control/meshes/motor.stl"
						scale="0.005 0.005 0.005" />
				</geometry>
			</visual>
			<collision>
				<origin xyz="0 0 0" rpy="0 0 0" />
				<geometry>
					<mesh filename="package://synapticon_ros2_control/meshes/motor.stl"
						scale="0.005 0.005 0.005" />
				</geometry>
			</collision>
		</link>

		<joint name="${prefix}joint1" type="continuous">
			<parent link="${prefix}motor_link1" />
			<child link="${prefix}flywheel_link1" />
			<origin xyz="0 0 0" rpy="0 0 0" />
			<axis xyz="0 0 1" />
			<dynamics damping="0.7" />
			<limit effort="100" velocity="1.0" />
		</joint>

		<link name="${prefix}flywheel_link1">
			<visual>
				<origin xyz="0 0 0" rpy="0 0 0" />
				<geometry>
					<mesh filename="package://synapticon_ros2_control/meshes/flywheel.stl"
						scale="0.005 0.005 0.005" />
				</geometry>
			</visual>
			<collision>
				<origin xyz="0 0 0" rpy="0 0 0" />
				<geometry>
					<mesh filename="package://synapticon_ros2_control/meshes/flywheel.stl"
						scale="0.005 0.005 0.005" />
				</geometry>
			</collision>
		</link>

		<joint name="${prefix}fixed_joint2" type="fixed">
			<parent link="${prefix}motor_link1" />
			<child link="${prefix}motor_link2" />
			<origin xyz="0 1.1 0" rpy="0 0 0" />
		</joint>

		<!-- Link 2 -->
		<link name="${prefix}motor_link2">
			<visual>
				<origin xyz="0 0 0" rpy="0 0 0" />
				<geometry>
					<mesh filename="package://synapticon_ros2_control/meshes/motor.stl"
						scale="0.005 0.005 0.005" />
				</geometry>
			</visual>
			<collision>
				<origin xyz="0 0 0" rpy="0 0 0" />
				<geometry>
					<mesh filename="package://synapticon_ros2_control/meshes/motor.stl"
						scale="0.005 0.005 0.005" />
				</geometry>
			</collision>
		</link>

		<joint name="${prefix}joint2" type="continuous">
			<parent link="${prefix}motor_link2" />
			<child link="${prefix}flywheel_link2" />
			<origin xyz="0 0 0" rpy="0 0 0" />
			<axis xyz="0 0 1" />
			<dynamics damping="0.7" />
			<limit effort="100" velocity="1.0" />
		</joint>

		<link name="${prefix}flywheel_link2">
			<visual>
				<origin xyz="0 0 0" rpy="0 0 0" />
				<geometry>
					<mesh filename="package://synapticon_ros2_control/meshes/flywheel.stl"
						scale="0.005 0.005 0.005" />
				</geometry>
			</visual>
			<collision>
				<origin xyz="0 0 0" rpy="0 0 0" />
				<geometry>
					<mesh filename="package://synapticon_ros2_control/meshes/flywheel.stl"
						scale="0.005 0.005 0.005" />
				</geometry>
			</collision>
		</link>

		<joint name="${prefix}fixed_joint3" type="fixed">
			<parent link="${prefix}motor_link2" />
			<child link="${prefix}motor_link3" />
			<origin xyz="0 1.1 0" rpy="0 0 0" />
		</joint>

		<!-- Link 3 -->
		<link name="${prefix}motor_link3">
			<visual>
				<origin xyz="0 0 0" rpy="0 0 0" />
				<geometry>
					<mesh filename="package://synapticon_ros2_control/meshes/motor.stl"
						scale="0.005 0.005 0.005" />
				</geometry>
			</visual>
			<collision>
				<origin xyz="0 0 0" rpy="0 0 0" />
				<geometry>
					<mesh filename="package://synapticon_ros2_control/meshes/motor.stl"
						scale="0.005 0.005 0.005" />
				</geometry>
			</collision>
		</link>

		<joint name="${prefix}joint3" type="continuous">
			<parent link="${prefix}motor_link3" />
			<child link="${prefix}flywheel_link3" />
			<origin xyz="0 0 0" rpy="0 0 0" />
			<axis xyz="0 0 1" />
			<dynamics damping="0.7" />
			<limit effort="100" velocity="1.0" />
		</joint>

		<link name="${prefix}flywheel_link3">
			<visual>
				<origin xyz="0 0 0" rpy="0 0 0" />
				<geometry>
					<mesh filename="package://synapticon_ros2_control/meshes/flywheel.stl"
						scale="0.005 0.005 0.005" />
				</geometry>
			</visual>
			<collision>
				<origin xyz="0 0 0" rpy="0 0 0" />
				<geometry>
					<mesh filename="package://synapticon_ros2_control/meshes/flywheel.stl"
						scale="0.005 0.005 0.005" />
				</geometry>
			</collision>
		</link>

		<joint name="${prefix}fixed_joint4" type="fixed">
			<parent link="${prefix}motor_link3" />
			<child link="${prefix}motor_link4" />
			<origin xyz="0 1.1 0" rpy="0 0 0" />
		</joint>

		<!-- Link 4 -->
		<link name="${prefix}motor_link4">
			<visual>
				<origin xyz="0 0 0" rpy="0 0 0" />
				<geometry>
					<mesh filename="package://synapticon_ros2_control/meshes/motor.stl"
						scale="0.005 0.005 0.005" />
				</geometry>
			</visual>
			<collision>
				<origin xyz="0 0 0" rpy="0 0 0" />
				<geometry>
					<mesh filename="package://synapticon_ros2_control/meshes/motor.stl"
						scale="0.005 0.005 0.005" />
				</geometry>
			</collision>
		</link>

		<joint name="${prefix}joint4" type="continuous">
			<parent link="${prefix}motor_link4" />
			<child link="${prefix}flywheel_link4" />
			<origin xyz="0 0 0" rpy="0 0 0" />
			<axis xyz="0 0 1" />
			<dynamics damping="0.7" />
			<limit effort="100" velocity="1.0" />
		</joint>

		<link name="${prefix}flywheel_link4">
			<visual>
				<origin xyz="0 0 0" rpy="0 0 0" />
				<geometry>
					<mesh filename="package://synapticon_ros2_control/meshes/flywheel.stl"
						scale="0.005 0.005 0.005" />
				</geometry>
			</visual>
			<collision>
				<origin xyz="0 0 0" rpy="0 0 0" />
				<geometry>
					<mesh filename="package://synapticon_ros2_control/meshes/flywheel.stl"
						scale="0.005 0.005 0.005" />
				</geometry>
			</collision>
		</link>

		<joint name="${prefix}fixed_joint5" type="fixed">
			<parent link="${prefix}motor_link4" />
			<child link="${prefix}motor_link5" />
			<origin xyz="0 1.1 0" rpy="0 0 0" />
		</joint>

		<!-- Link 5 -->
		<link name="${prefix}motor_link5">
			<visual>
				<origin xyz="0 0 0" rpy="0 0 0" />
				<geometry>
					<mesh filename="package://synapticon_ros2_control/meshes/motor.stl"
						scale="0.005 0.005 0.005" />
				</geometry>
			</visual>
			<collision>
				<origin xyz="0 0 0" rpy="0 0 0" />
				<geometry>
					<mesh filename="package://synapticon_ros2_control/meshes/motor.stl"
						scale="0.005 0.005 0.005" />
				</geometry>
			</collision>
		</link>

		<joint name="${prefix}joint5" type="continuous">
			<parent link="${prefix}motor_link5" />
			<child link="${prefix}flywheel_link5" />
			<origin xyz="0 0 0" rpy="0 0 0" />
			<axis xyz="0 0 1" />
			<dynamics damping="0.7" />
			<limit effort="100" velocity="1.0" />
		</joint>

		<link name="${prefix}flywheel_link5">
			<visual>
				<origin xyz="0 0 0" rpy="0 0 0" />
				<geometry>
					<mesh filename="package://synapticon_ros2_control/meshes/flywheel.stl"
						scale="0.005 0.005 0.005" />
				</geometry>
			</visual>
			<collision>
				<origin xyz="0 0 0" rpy="0 0 0" />
				<geometry>
					<mesh filename="package://synapticon_ros2_control/meshes/flywheel.stl"
						scale="0.005 0.005 0.005" />
				</geometry>
			</collision>
		</link>

		<joint name="${prefix}fixed_joint6" type="fixed">
			<parent link="${prefix}motor_link5" />
			<child link="${prefix}motor_link6" />
			<origin xyz="0 1.1 0" rpy="0 0 0" />
		</joint>

		<!-- Link 6 -->
		<link name="${prefix}motor_link6">
			<visual>
				<origin xyz="0 0 0" rpy="0 0 0" />
				<geometry>
					<mesh filename="package://synapticon_ros2_control/meshes/motor.stl"
						scale="0.005 0.005 0.005" />
				</geometry>
			</visual>
			<collision>
				<origin xyz="0 0 0" rpy="0 0 0" />
				<geometry>
					<mesh filename="package://synapticon_ros2_control/meshes/motor.stl"
						scale="0.005 0.005 0.005" />
				</geometry>
			</collision>
		</link>

		<joint name="${prefix}joint6" type="continuous">
			<parent link="${prefix}motor_link6" />
			<child link="${prefix}flywheel_link6" />
			<origin xyz="0 0 0" rpy="0 0 0" />
			<axis xyz="0 0 1" />
			<dynamics damping="0.7" />
			<limit effort="100" velocity="1.0" />
		</joint>

		<link name="${prefix}flywheel_link6">
			<visual>
				<origin xyz="0 0 0" rpy="0 0 0" />
				<geometry>
					<mesh filename="package://synapticon_ros2_control/meshes/flywheel.stl"
						scale="0.005 0.005 0.005" />
				</geometry>
			</visual>
			<collision>
				<origin xyz="0 0 0" rpy="0 0 0" />
				<geometry>
					<mesh filename="package://synapticon_ros2_control/meshes/flywheel.stl"
						scale="0.005 0.005 0.005" />
				</geometry>
			</collision>
		</link>

	</xacro:macro>

</robot>